#VRML_SIM R2021b utf8
WorldInfo {
  basicTimeStep 5
  coordinateSystem "NUE"
}
Viewpoint {
  orientation 0.08186468943960029 0.9929912555695746 0.08524399676996379 4.580855993597049
  position -5.045250519621816 1.0977369582103949 0.5297373820470735
  follow "agiletaur"
}
TexturedBackground {
}
Ramp30deg {
  translation 1.13484 -0.452114 -3.46256
  rotation 0 1 0 1.5708
  color 0.3 0.1 0.1
}
Robot {
  translation 0.0002870924871765243 0.23354044337122956 0.00014395246242748086
  rotation 0.000354366623270526 0.9999999199955643 0.00018556174631585313 3.141590070591054
  children [
    Accelerometer {
      name "ACCELEROMETER"
    }
    DEF BODY_SHAPE Shape {
      appearance PBRAppearance {
        transparency 0.5
        metalness 0
      }
      geometry Box {
        size 0.3 0.1 0.6
      }
      castShadows FALSE
    }
    Transform {
      translation 0.15 0 -0.25
      children [
        HingeJoint {
          jointParameters HingeJointParameters {
            position -3.6941447764443998e-06
            axis 0 0 1
          }
          device [
            PositionSensor {
              name "BL0 position sensor"
            }
            RotationalMotor {
              name "BL0 rotational motor"
              controlPID 45 1 0
              maxVelocity 1000
              minPosition -1
              maxPosition 1
              maxTorque 2000
            }
          ]
          endPoint Solid {
            translation 5.367149642294584e-06 0.0004611414248848369 -2.9803256013567675e-05
            rotation 0.9999999999896105 3.207112238604147e-06 -3.2393767937243473e-06 1.570806737780304
            children [
              DEF FL0_SHAPE Shape {
                appearance PBRAppearance {
                  baseColor 0 0 0
                  metalness 0
                }
                geometry Cylinder {
                  height 0.05
                  radius 0.025
                }
                castShadows FALSE
              }
              Transform {
                children [
                  HingeJoint {
                    jointParameters HingeJointParameters {
                      position 0.5252863085095791
                      minStop -0.55
                      maxStop 1.7
                    }
                    device [
                      PositionSensor {
                        name "BL1 position sensor"
                      }
                      RotationalMotor {
                        name "BL1 rotational motor"
                        controlPID 370 1 0
                        maxVelocity 1000
                        minPosition -1
                        maxPosition 1
                        maxTorque 2000
                      }
                    ]
                    endPoint Solid {
                      translation 0 -0.050249977706314626 0.08658860179145736
                      rotation 0.9999999999999999 0 0 2.096086308509578
                      children [
                        DEF FL1_SHAPE Shape {
                          appearance PBRAppearance {
                            metalness 0
                          }
                          geometry Capsule {
                            height 0.2
                            radius 0.02
                          }
                          castShadows FALSE
                        }
                        Transform {
                          translation 0 0.1 0
                          children [
                            HingeJoint {
                              jointParameters HingeJointParameters {
                                position -1.0508633972646393
                                minStop -2.2
                                maxStop -0.05
                              }
                              device [
                                PositionSensor {
                                  name "BL2 position sensor"
                                }
                                RotationalMotor {
                                  name "BL2 rotational motor"
                                  controlPID 370 1 0
                                  maxVelocity 1000
                                  maxTorque 2000
                                }
                              ]
                              endPoint Solid {
                                translation 0 0.05195829218199312 -0.08553744013249645
                                rotation -1 -1.4338245620162242e-09 -2.1181156689865503e-11 1.0480633972668434
                                children [
                                  DEF FL2_SHAPE Shape {
                                    appearance PBRAppearance {
                                      baseColor 0 0 0
                                      metalness 0
                                    }
                                    geometry Cylinder {
                                      height 0.2
                                      radius 0.02
                                    }
                                    castShadows FALSE
                                  }
                                  Transform {
                                    translation 0 0.1 0
                                    children [
                                      DEF FL_FOOT Shape {
                                        appearance PBRAppearance {
                                          metalness 0
                                        }
                                        geometry Sphere {
                                          radius 0.04
                                          subdivision 2
                                        }
                                      }
                                      TouchSensor {
                                        translation 2.5998477454214353e-08 -2.993635621166557e-05 -1.726608989760514e-05
                                        rotation -1 5.197125226337797e-11 -3.0062192179644755e-11 1.047200306130269
                                        name "BL touch sensor"
                                        boundingObject USE FL_FOOT
                                        physics Physics {
                                          density -1
                                          mass 0.01
                                        }
                                        type "force"
                                        lookupTable [
                                          0 0 0
                                          5000 50000 500
                                        ]
                                      }
                                    ]
                                  }
                                ]
                                boundingObject USE FL2_SHAPE
                                physics Physics {
                                  density -1
                                  mass 1
                                }
                              }
                            }
                          ]
                          rotationStep 0.262
                        }
                      ]
                      boundingObject USE FL1_SHAPE
                      physics Physics {
                        density -1
                        mass 1
                      }
                    }
                  }
                ]
              }
            ]
            name "solid(4)"
            boundingObject USE FL0_SHAPE
            physics Physics {
              density -1
              mass 0.5
            }
          }
        }
      ]
    }
    Transform {
      translation -0.15 0 -0.25
      children [
        HingeJoint {
          jointParameters HingeJointParameters {
            position -3.68000853582188e-06
            axis 0 0 1
          }
          device [
            PositionSensor {
              name "BR0 position sensor"
            }
            RotationalMotor {
              name "BR0 rotational motor"
              controlPID 45 1 0
              maxVelocity 1000
              minPosition -1
              maxPosition 1
              maxTorque 2000
            }
          ]
          endPoint Solid {
            translation 4.712238463128583e-06 7.190865633452363e-05 4.8184438331268495e-06
            rotation 0.9999999999878014 2.205429501915934e-06 -4.419649622105415e-06 1.5707896719425287
            children [
              DEF FL0_SHAPE Shape {
                appearance PBRAppearance {
                  baseColor 0 0 0
                  metalness 0
                }
                geometry Cylinder {
                  height 0.05
                  radius 0.025
                }
                castShadows FALSE
              }
              Transform {
                children [
                  HingeJoint {
                    jointParameters HingeJointParameters {
                      position 0.5252862817825873
                      minStop -0.55
                      maxStop 1.7
                    }
                    device [
                      PositionSensor {
                        name "BR1 position sensor"
                      }
                      RotationalMotor {
                        name "BR1 rotational motor"
                        controlPID 370 1 0
                        maxVelocity 1000
                        maxTorque 2000
                      }
                    ]
                    endPoint Solid {
                      translation 0 -0.05024997539206154 0.08658860313448773
                      rotation 1 0 0 2.0960862817825823
                      children [
                        DEF FL1_SHAPE Shape {
                          appearance PBRAppearance {
                            metalness 0
                          }
                          geometry Capsule {
                            height 0.2
                            radius 0.02
                          }
                          castShadows FALSE
                        }
                        Transform {
                          translation 0 0.1 0
                          children [
                            HingeJoint {
                              jointParameters HingeJointParameters {
                                position -1.0508634541363955
                                minStop -2.2
                                maxStop -0.05
                              }
                              device [
                                PositionSensor {
                                  name "BR2 position sensor"
                                }
                                RotationalMotor {
                                  name "BR2 rotational motor"
                                  controlPID 370 1 0
                                  maxVelocity 1000
                                  maxTorque 2000
                                }
                              ]
                              endPoint Solid {
                                translation 0 0.051958287317328586 -0.08553744308745564
                                rotation -1 -1.4338244922220589e-09 -2.118111487787987e-11 1.0480634541382823
                                children [
                                  DEF FL2_SHAPE Shape {
                                    appearance PBRAppearance {
                                      baseColor 0 0 0
                                      metalness 0
                                    }
                                    geometry Cylinder {
                                      height 0.2
                                      radius 0.02
                                    }
                                    castShadows FALSE
                                  }
                                  Transform {
                                    translation 0 0.1 0
                                    children [
                                      DEF FL_FOOT Shape {
                                        appearance PBRAppearance {
                                          metalness 0
                                        }
                                        geometry Sphere {
                                          radius 0.04
                                          subdivision 2
                                        }
                                      }
                                      TouchSensor {
                                        translation 2.9016447106178234e-08 -3.495003738114566e-05 -2.0156674043148026e-05
                                        rotation -1 1.7488768263364318e-11 -1.0082170113066432e-11 1.0472003060692836
                                        name "BR touch sensor"
                                        boundingObject USE FL_FOOT
                                        physics Physics {
                                          density -1
                                          mass 0.01
                                        }
                                        type "force"
                                      }
                                    ]
                                  }
                                ]
                                boundingObject USE FL2_SHAPE
                                physics Physics {
                                  density -1
                                  mass 1
                                }
                              }
                            }
                          ]
                          rotationStep 0.262
                        }
                      ]
                      boundingObject USE FL1_SHAPE
                      physics Physics {
                        density -1
                        mass 1
                      }
                    }
                  }
                ]
              }
            ]
            name "solid(2)"
            boundingObject USE FL0_SHAPE
            physics Physics {
              density -1
              mass 0.5
            }
          }
        }
      ]
    }
    Transform {
      translation -0.15 0 0.25
      children [
        HingeJoint {
          jointParameters HingeJointParameters {
            position -3.6950565377774998e-06
            axis 0 0 1
          }
          device [
            PositionSensor {
              name "FR0 position sensor"
            }
            RotationalMotor {
              name "FR0 rotational motor"
              controlPID 45 1 0
              maxVelocity 1000
              maxTorque 2000
            }
          ]
          endPoint Solid {
            translation 6.160741594051187e-05 0.000612136460356917 -6.798457252921427e-05
            rotation 0.9999999999909076 1.6219709820035009e-06 -3.9438922447438075e-06 1.570818156954289
            children [
              DEF FL0_SHAPE Shape {
                appearance PBRAppearance {
                  baseColor 0 0 0
                  metalness 0
                }
                geometry Cylinder {
                  height 0.05
                  radius 0.025
                }
                castShadows FALSE
              }
              Transform {
                children [
                  HingeJoint {
                    jointParameters HingeJointParameters {
                      position 0.5252863070661391
                      minStop -0.55
                      maxStop 1.7
                    }
                    device [
                      PositionSensor {
                        name "FR1 position sensor"
                      }
                      RotationalMotor {
                        name "FR1 rotational motor"
                        controlPID 370 1 0
                        maxVelocity 1000
                        maxTorque 2000
                      }
                    ]
                    endPoint Solid {
                      translation 0 -0.05024997758132879 0.08658860186398942
                      rotation 1 0 0 2.0960863070661344
                      children [
                        DEF FL1_SHAPE Shape {
                          appearance PBRAppearance {
                            metalness 0
                          }
                          geometry Capsule {
                            height 0.2
                            radius 0.02
                          }
                          castShadows FALSE
                        }
                        Transform {
                          translation 0 0.1 0
                          children [
                            HingeJoint {
                              jointParameters HingeJointParameters {
                                position -1.0508633849359963
                                minStop -2.2
                                maxStop -0.05
                              }
                              device [
                                PositionSensor {
                                  name "FR2 position sensor"
                                }
                                RotationalMotor {
                                  name "FR2 rotational motor"
                                  controlPID 370 1 0
                                  maxVelocity 1000
                                  maxTorque 2000
                                }
                              ]
                              endPoint Solid {
                                translation 0 0.05195829323655351 -0.08553743949192097
                                rotation -1 -1.4338245771663173e-09 -2.1181165754159465e-11 1.0480633849381995
                                children [
                                  DEF FL2_SHAPE Shape {
                                    appearance PBRAppearance {
                                      baseColor 0 0 0
                                      metalness 0
                                    }
                                    geometry Cylinder {
                                      height 0.2
                                      radius 0.02
                                    }
                                    castShadows FALSE
                                  }
                                  Transform {
                                    translation 0 0.1 0
                                    children [
                                      DEF FL_FOOT Shape {
                                        appearance PBRAppearance {
                                          metalness 0
                                        }
                                        geometry Sphere {
                                          radius 0.04
                                          subdivision 2
                                        }
                                      }
                                      TouchSensor {
                                        translation 2.50445876259775e-08 -2.8903723184009467e-05 -1.667028896740197e-05
                                        rotation -1 5.083420602481101e-11 -2.9411111192106493e-11 1.0472003061368833
                                        name "FR touch sensor"
                                        boundingObject USE FL_FOOT
                                        physics Physics {
                                          density -1
                                          mass 0.01
                                        }
                                        type "force"
                                      }
                                    ]
                                  }
                                ]
                                boundingObject USE FL2_SHAPE
                                physics Physics {
                                  density -1
                                  mass 1
                                }
                              }
                            }
                          ]
                          rotationStep 0.262
                        }
                      ]
                      boundingObject USE FL1_SHAPE
                      physics Physics {
                        density -1
                        mass 1
                      }
                    }
                  }
                ]
              }
            ]
            name "solid(1)"
            boundingObject USE FL0_SHAPE
            physics Physics {
              density -1
              mass 0.5
            }
          }
        }
      ]
    }
    Transform {
      translation 0.15 0 0.25
      children [
        HingeJoint {
          jointParameters HingeJointParameters {
            position -3.3594714881299866e-06
            axis 0 0 1
          }
          device [
            PositionSensor {
              name "FL0 position sensor"
            }
            RotationalMotor {
              name "FL0 rotational motor"
              controlPID 45 1 0
              maxVelocity 1000
              maxTorque 2000
            }
          ]
          endPoint Solid {
            translation 4.220871360282321e-06 -0.00017648530762287614 0.00023335742653378104
            rotation 0.9999998893954857 0.0003414313283686524 -0.0003234712727522216 1.5708540162939866
            children [
              DEF FL0_SHAPE Shape {
                appearance PBRAppearance {
                  baseColor 0 0 0
                  metalness 0
                }
                geometry Cylinder {
                  height 0.05
                  radius 0.025
                }
                castShadows FALSE
              }
              Transform {
                children [
                  HingeJoint {
                    jointParameters HingeJointParameters {
                      position 0.5252862802702584
                      minStop -0.55
                      maxStop 1.7
                    }
                    device [
                      PositionSensor {
                        name "FL1 position sensor"
                      }
                      RotationalMotor {
                        name "FL1 rotational motor"
                        controlPID 370 1 0
                        maxVelocity 1000
                        maxTorque 2000
                      }
                    ]
                    endPoint Solid {
                      translation 0 -0.05024997526111124 0.08658860321048265
                      rotation 1 0 0 2.0960862802702573
                      children [
                        DEF FL1_SHAPE Shape {
                          appearance PBRAppearance {
                            metalness 0
                          }
                          geometry Capsule {
                            height 0.2
                            radius 0.02
                          }
                          castShadows FALSE
                        }
                        Transform {
                          translation 0 0.1 0
                          children [
                            HingeJoint {
                              jointParameters HingeJointParameters {
                                position -1.0508634387357147
                                minStop -2.2
                                maxStop -0.05
                              }
                              device [
                                PositionSensor {
                                  name "FL2 position sensor"
                                }
                                RotationalMotor {
                                  name "FL2 rotational motor"
                                  controlPID 370 1 0
                                  maxVelocity 1000
                                  maxTorque 2000
                                }
                              ]
                              endPoint Solid {
                                translation 0 0.0519582886346634 -0.08553744228726262
                                rotation -1 -1.4338245108518345e-09 -2.1181126196435167e-11 1.0480634387382362
                                children [
                                  DEF FL2_SHAPE Shape {
                                    appearance PBRAppearance {
                                      baseColor 0 0 0
                                      metalness 0
                                    }
                                    geometry Cylinder {
                                      height 0.2
                                      radius 0.02
                                    }
                                    castShadows FALSE
                                  }
                                  Transform {
                                    translation 0 0.1 0
                                    children [
                                      DEF FL_FOOT Shape {
                                        appearance PBRAppearance {
                                          metalness 0
                                        }
                                        geometry Sphere {
                                          radius 0.04
                                          subdivision 2
                                        }
                                      }
                                      TouchSensor {
                                        translation 2.8197030099708087e-08 -3.370183403833549e-05 -1.9433468015417343e-05
                                        rotation -1 -2.0433271000553378e-12 1.2198533268034692e-12 1.047200306054173
                                        name "FL touch sensor"
                                        boundingObject USE FL_FOOT
                                        physics Physics {
                                          density -1
                                          mass 0.01
                                        }
                                        type "force"
                                        lookupTable [
                                          0 0 0
                                          5000 50000 500
                                        ]
                                      }
                                    ]
                                  }
                                ]
                                boundingObject USE FL2_SHAPE
                                physics Physics {
                                  density -1
                                  mass 1
                                }
                              }
                            }
                          ]
                          rotationStep 0.262
                        }
                      ]
                      boundingObject USE FL1_SHAPE
                      physics Physics {
                        density -1
                        mass 1
                      }
                    }
                  }
                ]
              }
            ]
            name "solid(3)"
            boundingObject USE FL0_SHAPE
            physics Physics {
              density -1
              mass 0.5
            }
          }
        }
      ]
    }
    InertialUnit {
      translation -6.362582630762203e-13 -4.414499965577079e-08 -4.0534315675068254e-15
      rotation 0 0.9701425001453319 0.24253562503633297 1.04081818756691e-28
      children [
        Shape {
          geometry Box {
            size 0.05 0.05 0.05
          }
          castShadows FALSE
        }
      ]
      boundingObject USE BODY_SHAPE
      physics Physics {
        density -1
        mass 0.01
      }
    }
  ]
  name "12dof"
  boundingObject USE BODY_SHAPE
  physics Physics {
    density -1
    mass 50
  }
  controller "<extern>"
  supervisor TRUE
  linearVelocity 1.3891114843076307e-05 -2.801215207983023e-07 4.957670714008727e-07
  angularVelocity -4.129662063378574e-06 -3.6971505089871055e-06 -3.864130212228845e-05
}
TexturedBackgroundLight {
}
RectangleArena {
  translation 0 -0.15 0
  rotation 0 1 0 3.14159
  floorSize 11 16
  floorTileSize 1.2 0.5
  floorAppearance Parquetry {
    type "dark strip"
  }
  wallHeight 0.5
}
