#VRML_SIM R2021a utf8
WorldInfo {
  basicTimeStep 5
  coordinateSystem "NUE"
}
Viewpoint {
  orientation -0.01614336456060554 0.9985495600762041 0.05136309815697194 2.840519959720434
  position 2.802687240533514 -0.02275652779522236 -7.984089904604378
  follow "robot(2)"
}
TexturedBackground {
}
Robot {
  translation 2.86416 -0.140426 -4.6702
  rotation 1.9687599986429358e-05 0.9999999993107009 -3.1480099978300795e-05 1.57085
  children [
    Lidar {
      translation 0 0.07 -0.16
      children [
        HokuyoUtm30lx {
          translation 0 0.03 -0.01
          enablePhysics FALSE
        }
      ]
    }
    GPS {
    }
    InertialUnit {
      translation 0 0.05 0
      name "imu"
    }
    DEF body Group {
      children [
        Shape {
          appearance Appearance {
            material Material {
              diffuseColor 0.666667 0 0.498039
            }
          }
          geometry Box {
            size 0.152 0.09 0.43
          }
        }
        Transform {
          translation 0.132 0 0
          children [
            Shape {
              appearance Appearance {
                material Material {
                  diffuseColor 0 0.333333 0
                }
              }
            }
          ]
        }
        Transform {
          translation -0.132 0 0
        }
        Transform {
          translation 0.184 0 0
        }
        Transform {
          translation -0.184 0 0
        }
      ]
    }
    DEF fr_6 HingeJoint {
      jointParameters HingeJointParameters {
        position 0.25269369558435795
        anchor -0.096 0 0.17
      }
      device [
        PositionSensor {
          name "pos_6"
        }
        RotationalMotor {
          name "motor_6"
          controlPID 15 0 0.5
          maxVelocity 94.2
          maxTorque 21
        }
      ]
      endPoint Solid {
        translation -0.09599941548482116 -3.930899902700803e-05 0.16998136362798202
        rotation 0.1225604668563616 -0.12288459745551306 0.9848239983226177 1.586183177663132
        children [
          DEF kuan_1 Shape {
            appearance Appearance {
              material Material {
                diffuseColor 1 0.333333 0
              }
            }
            geometry Cylinder {
              height 0.04
              radius 0.045
            }
          }
          DEF kuan_2 Group {
            children [
              Transform {
                translation 0 0.026 0
                children [
                  Shape {
                    appearance Appearance {
                      material Material {
                        diffuseColor 0.5 0.5 0.5
                      }
                    }
                    geometry Cylinder {
                      height 0.012
                      radius 0.02
                    }
                  }
                ]
              }
              Transform {
                translation 0 0.026 0.05
                children [
                  Shape {
                    appearance Appearance {
                      material Material {
                        diffuseColor 0.5 0.5 0.5
                      }
                    }
                    geometry Box {
                      size 0.03 0.012 0.1
                    }
                  }
                ]
              }
              Transform {
                translation 0 0.026 0.1
                children [
                  Shape {
                    appearance Appearance {
                      material Material {
                        diffuseColor 0.5 0.5 0.5
                      }
                    }
                    geometry Cylinder {
                      height 0.012
                      radius 0.02
                    }
                  }
                ]
              }
            ]
          }
          HingeJoint {
            jointParameters HingeJointParameters {
              position 0.270910206291762
              axis 0 1 0
              anchor 0 0.03 0.1
            }
            endPoint Solid {
              translation 0 0.03 0.1
              rotation 0 1 0 1.317910206291713
              children [
                DEF XI Group {
                  children [
                    Transform {
                      translation 0 -0.004 -0.115
                      children [
                        Shape {
                          appearance Appearance {
                            material Material {
                              diffuseColor 0.5 0.5 0.5
                            }
                          }
                          geometry Box {
                            size 0.02 0.01 0.23
                          }
                        }
                      ]
                    }
                    Transform {
                      translation 0 -0.004 -0.23
                      children [
                        DEF foot Shape {
                          appearance Appearance {
                            material Material {
                              diffuseColor 0 0.666667 0
                            }
                          }
                          geometry Sphere {
                            radius 0.015
                          }
                        }
                      ]
                    }
                  ]
                }
                Transform {
                  translation 0 -0.004 -0.23
                  children [
                    TouchSensor {
                      translation 4.7584549889290173e-07 -1.922515480146103e-10 1.1584379042695048e-06
                      rotation -0.1641818983692368 -0.013681824864103067 -0.9863351924757939 4.463020610254437e-14
                      name "Foot_C"
                      boundingObject USE foot
                      physics Physics {
                      }
                    }
                  ]
                }
              ]
              name "solid_xi_"
              boundingObject USE XI
              physics Physics {
                density -1
                mass 0.25
              }
            }
          }
        ]
        boundingObject USE kuan_1
        physics Physics {
          density -1
          mass 0.25
        }
      }
    }
    DEF fl_7 HingeJoint {
      jointParameters HingeJointParameters {
        position 0.2526936982763569
        anchor 0.096 0 0.17
      }
      device [
        RotationalMotor {
          name "motor_7"
          controlPID 15 0 0.5
          maxVelocity 94.2
          maxTorque 21
        }
        PositionSensor {
          name "pos_7"
        }
      ]
      endPoint Solid {
        translation 0.09600057359229108 -3.9306390496339196e-05 0.16998137274669617
        rotation 0.12256072732645076 -0.1228843556686565 0.98482399607702 1.5861830709339018
        children [
          Transform {
            translation 0 -0.052 0
            children [
              USE kuan_2
            ]
          }
          DEF fl_1 Shape {
            appearance Appearance {
              material Material {
                diffuseColor 1 0.333333 0
              }
            }
            geometry Cylinder {
              height 0.04
              radius 0.045
            }
          }
          HingeJoint {
            jointParameters HingeJointParameters {
              position 0.270900509536267
              axis 0 1 0
              anchor 0 -0.052 0.1
            }
            endPoint Solid {
              translation 0 -0.022000000000000068 0.1
              rotation 0 0.9999999999999999 0 1.3179005095362166
              children [
                TouchSensor {
                  translation 4.780419991801121e-07 -0.004000000193125075 -0.2299988362343856
                  rotation 0.5268379287975528 -0.004737751158251374 -0.8499525577902965 5.858386117913597e-14
                  name "Foot_D"
                  boundingObject USE foot
                  physics Physics {
                  }
                }
                USE XI
              ]
              name "solid_fl"
              boundingObject USE XI
              physics Physics {
                density -1
                mass 0.25
              }
            }
          }
        ]
        name "solid(1)"
        boundingObject USE fl_1
        physics Physics {
          density -1
          mass 0.25
        }
      }
    }
    DEF rl_3 HingeJoint {
      jointParameters HingeJointParameters {
        position 0.25269365069935856
        anchor 0.096 0 -0.17
      }
      device [
        RotationalMotor {
          name "motor_3"
          controlPID 15 0 0.5
          maxVelocity 94.2
          maxTorque 21
        }
        PositionSensor {
          name "pos_3"
        }
      ]
      endPoint Solid {
        translation 0.09600057031346965 -3.9590594326738125e-05 -0.17001899446609423
        rotation 0.12256071211795401 -0.12288432390414415 0.9848240019332192 1.5861830511390151
        children [
          DEF rl_1 Shape {
            appearance Appearance {
              material Material {
                diffuseColor 1 0.333333 0
              }
            }
            geometry Cylinder {
              height 0.04
              radius 0.045
            }
          }
          Transform {
            translation 0 -0.052 0
            children [
              USE kuan_2
            ]
          }
          HingeJoint {
            jointParameters HingeJointParameters {
              position 0.27089486160135595
              axis 0 1 0
              anchor 0 -0.06 0.1
            }
            endPoint Solid {
              translation 0 -0.02200000000004817 0.1
              rotation 0 1 0 1.3178948616013353
              children [
                TouchSensor {
                  translation 5.238021911768698e-07 -0.004000000211533461 -0.22999872523678638
                  rotation 0.06089581593249515 0.016069729204408443 0.9980147611158927 -6.563345654291158e-14
                  name "Foot_B"
                  boundingObject USE foot
                  physics Physics {
                  }
                }
                USE XI
              ]
              name "rl_solid"
              boundingObject USE XI
              physics Physics {
                density -1
                mass 0.25
              }
            }
          }
        ]
        name "solid(2)"
        boundingObject USE rl_1
        physics Physics {
          density -1
          mass 0.25
        }
      }
    }
    DEF rr_2 HingeJoint {
      jointParameters HingeJointParameters {
        position 0.2526936506439035
        anchor -0.096 0 -0.17
      }
      device [
        PositionSensor {
          name "pos_2"
        }
        RotationalMotor {
          name "motor_2"
          controlPID 15 0 0.5
          maxVelocity 94.2
          maxTorque 21
        }
      ]
      endPoint Solid {
        translation -0.09599945582510272 -3.959258332096766e-05 -0.17001900370983153
        rotation 0.1225605513240773 -0.12288450319456035 0.9848239995723927 1.586182852081466
        children [
          DEF rr_1 Shape {
            appearance Appearance {
              material Material {
                diffuseColor 1 0.333333 0
              }
            }
            geometry Cylinder {
              height 0.04
              radius 0.045
            }
          }
          Transform {
            children [
              USE kuan_2
            ]
          }
          HingeJoint {
            jointParameters HingeJointParameters {
              position 0.27090415085748265
              axis 0 1 0
              anchor 0 0 0.1
            }
            endPoint Solid {
              translation 0 0.03000000000012336 0.1
              rotation 0 1 0 1.3179041508574443
              children [
                TouchSensor {
                  translation 5.21874521541843e-07 -0.004000000210777621 -0.2299987299110326
                  rotation 0.04795573547968432 0 -0.9988494618482819 4.0514242429189686e-14
                  name "Foot_A"
                  boundingObject USE foot
                  physics Physics {
                  }
                }
                USE XI
              ]
              name "rr_solid"
              boundingObject USE XI
              physics Physics {
                density -1
                mass 0.25
              }
            }
          }
        ]
        name "solid(3)"
        boundingObject USE rr_1
        physics Physics {
          density -1
          mass 0.25
        }
      }
    }
    DEF fr_5 HingeJoint {
      jointParameters HingeJointParameters {
        position -0.2526671584132263
        anchor -0.16 0 0.17
      }
      device [
        PositionSensor {
          name "pos_5"
        }
        RotationalMotor {
          name "motor_5"
          controlPID 15 0 0.5
          maxVelocity 94.2
          maxTorque 21
        }
      ]
      endPoint Solid {
        translation -0.16000057987340388 -4.6253296620596526e-05 0.1700243483797177
        rotation -0.12713186403721305 0.12745587011007317 0.9836627929940767 1.5873789850072866
        children [
          USE kuan_1
          DEF kuan_3 Group {
            children [
              Transform {
                translation 0 -0.026 0
                children [
                  Shape {
                    appearance Appearance {
                      material Material {
                      }
                    }
                    geometry Cylinder {
                      height 0.012
                      radius 0.02
                    }
                  }
                ]
              }
              Transform {
                translation 0 -0.026 -0.05
                children [
                  Shape {
                    appearance Appearance {
                      material Material {
                      }
                    }
                    geometry Box {
                      size 0.02 0.012 0.1
                    }
                  }
                ]
              }
              Transform {
                translation 0 -0.026 -0.1
                children [
                  Shape {
                    appearance Appearance {
                      material Material {
                      }
                    }
                    geometry Cylinder {
                      height 0.012
                      radius 0.02
                    }
                  }
                ]
              }
            ]
          }
          HingeJoint {
            jointParameters HingeJointParameters {
              position -0.2708963106796347
              axis 0 1 0
              anchor 0 -0.026 -0.1
            }
            endPoint Solid {
              translation 0 -0.026 -0.1
              rotation 0 -1 0 1.3178963106795896
              children [
                DEF xi_2 Transform {
                  translation 0 0 0.1
                  children [
                    Shape {
                      appearance Appearance {
                        material Material {
                        }
                      }
                      geometry Box {
                        size 0.02 0.012 0.2
                      }
                    }
                  ]
                }
                HingeJoint {
                  jointParameters HingeJointParameters {
                    position 0.036460780537211565
                    axis 0 1 0
                    anchor 0 0 0.2
                  }
                  endPoint SolidReference {
                    solidName "solid_xi_"
                  }
                }
              ]
              name "solid(6)"
              boundingObject USE xi_2
              physics Physics {
                density -1
                mass 0.25
              }
            }
          }
        ]
        name "solid(6)"
        boundingObject USE kuan_1
        physics Physics {
          density -1
          mass 0.25
        }
      }
    }
    DEF fl_8 HingeJoint {
      jointParameters HingeJointParameters {
        position -0.2526671584866201
        anchor 0.16 0 0.17
      }
      device [
        RotationalMotor {
          name "motor_8"
          controlPID 15 0 0.5
          maxVelocity 94.2
          maxTorque 21
        }
        PositionSensor {
          name "pos_8"
        }
      ]
      endPoint Solid {
        translation 0.15999943105918057 -4.623983853806704e-05 0.17002433516230392
        rotation -0.12713158383336476 0.1274560870660439 0.9836628010969172 1.5873794696492955
        children [
          USE kuan_1
          Transform {
            translation 0 0.052 0
            children [
              USE kuan_3
            ]
          }
          HingeJoint {
            jointParameters HingeJointParameters {
              position -0.27089513899911544
              axis 0 1 0
              anchor 0 0 -0.1
            }
            endPoint Solid {
              translation 0 0.025999999999876327 -0.1
              rotation 0 -1 0 1.3178951389990852
              children [
                USE xi_2
                HingeJoint {
                  jointParameters HingeJointParameters {
                    position 0.03645002225051067
                    axis 0 1 0
                    anchor 0 0 0.2
                  }
                  endPoint SolidReference {
                    solidName "solid_fl"
                  }
                }
              ]
              boundingObject USE xi_2
              physics Physics {
                density -1
                mass 0.25
              }
            }
          }
        ]
        name "solid(4)"
        boundingObject USE kuan_1
        physics Physics {
          density -1
          mass 0.25
        }
      }
    }
    DEF rl_4 HingeJoint {
      jointParameters HingeJointParameters {
        position -0.25266715847512144
        anchor 0.16 0 -0.17
      }
      device [
        RotationalMotor {
          name "motor_4"
          controlPID 15 0 0.5
          maxVelocity 94.2
          maxTorque 21
        }
        PositionSensor {
          name "pos_4"
        }
      ]
      endPoint Solid {
        translation 0.15999943450623233 -4.6646162473708126e-05 -0.16997526176701924
        rotation -0.12713157846276277 0.1274560888179181 0.9836628015640347 1.587379493500005
        children [
          USE kuan_1
          Transform {
            translation 0 0.052 0
            children [
              USE kuan_3
            ]
          }
          HingeJoint {
            jointParameters HingeJointParameters {
              position -0.27089054499575593
              axis 0 1 0
              anchor 0 0 -0.1
            }
            endPoint Solid {
              translation 0 0.025999999999985993 -0.1
              rotation 0 -1 0 1.3178905449957468
              children [
                USE xi_2
                HingeJoint {
                  jointParameters HingeJointParameters {
                    position 0.03644816655384792
                    axis 0 1 0
                    anchor 0 0 0.2
                  }
                  endPoint SolidReference {
                    solidName "rl_solid"
                  }
                }
              ]
              boundingObject USE xi_2
              physics Physics {
                density -1
                mass 0.25
              }
            }
          }
        ]
        name "solid(5)"
        boundingObject USE kuan_1
        physics Physics {
          density -1
          mass 0.25
        }
      }
    }
    DEF rr_1 HingeJoint {
      jointParameters HingeJointParameters {
        position -0.2526671584128039
        anchor -0.16 0 -0.17
      }
      device [
        RotationalMotor {
          name "motor_1"
          controlPID 15 0 0.5
          maxVelocity 94.2
          maxTorque 21
        }
        PositionSensor {
          name "pos_1"
        }
      ]
      endPoint Solid {
        translation -0.1600005393708559 -4.666007401732402e-05 -0.16997524809884862
        rotation -0.1271319141654617 0.12745580526999561 0.9836627949168367 1.5873790817428939
        children [
          Transform {
            translation 0 -0.052 -0.1
            children [
              USE kuan_2
            ]
          }
          USE kuan_1
          HingeJoint {
            jointParameters HingeJointParameters {
              position -0.27089133294398077
              axis 0 1 0
              anchor 0 0 -0.1
            }
            endPoint Solid {
              translation 0 -0.03799999999992404 -0.1
              rotation 0 -1 0 1.3178913329439526
              children [
                USE xi_2
                HingeJoint {
                  jointParameters HingeJointParameters {
                    position 0.036457975879578976
                    axis 0 1 0
                    anchor 0 0 0.2
                  }
                  endPoint SolidReference {
                    solidName "rr_solid"
                  }
                }
              ]
              boundingObject USE xi_2
              physics Physics {
                density -1
                mass 0.25
              }
            }
          }
        ]
        name "solid(7)"
        boundingObject USE kuan_1
        physics Physics {
          density -1
          mass 0.25
        }
      }
    }
  ]
  name "robot(2)"
  boundingObject USE body
  physics Physics {
    density -1
    mass 5
  }
  controller "moco8_vs"
}
Ramp30deg {
  translation 0.623055 -1.15717 -4.69
  rotation 0 0 1 -0.261795307179586
}
TexturedBackgroundLight {
}
UnevenTerrain {
  translation 0 -3.6 8.94
}
Rock17cm {
  translation -0.68 -0.17 0.67
}
Rock17cm {
  translation -0.8 -0.17 0.49
  name "rock 17 cm(12)"
}
Rock17cm {
  translation -0.68 -0.15 1.64
  name "rock 17 cm(8)"
}
Rock17cm {
  translation -0.68 -0.15 1.96
  rotation 0 1 0 1.0472
  name "rock 17 cm(20)"
}
Rock17cm {
  translation -0.93 -0.13 0.88
  rotation 2.31518e-08 -1 -9.58979e-09 -0.785395307179586
  name "rock 17 cm(3)"
}
Rock17cm {
  translation -1.12797 -0.15 0.682012
  rotation 0 1 0 0.785398
  name "rock 17 cm(11)"
}
Rock17cm {
  translation -0.68 -0.15 0.99
  rotation 0 1 0 0.785398
  name "rock 17 cm(2)"
}
Rock17cm {
  translation -0.453728 -0.16 1.11726
  rotation 0 1 0 1.309
  name "rock 17 cm(24)"
}
Rock17cm {
  translation -0.85867 -0.16 1.0838
  rotation 0 1 0 1.8326
  name "rock 17 cm(23)"
}
Rock17cm {
  translation -0.453728 -0.15 0.763728
  rotation 0 1 0 0.785398
  name "rock 17 cm(7)"
}
Rock17cm {
  translation -0.835562 -0.16 1.40006
  rotation 0 1 0 0.785398
  name "rock 17 cm(6)"
}
Rock17cm {
  translation -1.15374 -0.16 1.46369
  rotation 0 1 0 0.785398
  name "rock 17 cm(4)"
}
Rock17cm {
  translation -1.26686 -0.19 1.57681
  rotation 0 1 0 0.785398
  name "rock 17 cm(14)"
}
Rock17cm {
  translation -1.18 -0.16 1.08
  name "rock 17 cm(1)"
}
Rock17cm {
  translation -1.06 -0.17 1.26
  name "rock 17 cm(10)"
}
Rock17cm {
  translation -0.46 -0.18 1.34
  name "rock 17 cm(9)"
}
Rock17cm {
  translation -0.49 -0.16 1.57
  name "rock 17 cm(13)"
}
Rock17cm {
  translation -0.79 -0.22 1.86
  name "rock 17 cm(15)"
}
Rock17cm {
  translation -0.45 -0.18 1.86
  rotation 0 1 0 -0.785395307179586
  name "rock 17 cm(16)"
}
Rock17cm {
  translation -0.79 -0.18 2.12
  rotation 0 1 0 0.523599
  name "rock 17 cm(17)"
}
Rock17cm {
  translation -0.56 -0.19 2.27
  rotation 0 1 0 1.309
  name "rock 17 cm(18)"
}
Rock17cm {
  translation -1.04297 -0.2 2.14055
  rotation 0 1 0 -0.523595307179586
  name "rock 17 cm(19)"
}
Rock17cm {
  translation -1.26702 -0.18 2.04941
  rotation 0 1 0 2.618
  name "rock 17 cm(21)"
}
Rock17cm {
  translation -0.913809 -0.21 2.39262
  rotation 0 1 0 1.309
  name "rock 17 cm(22)"
}
Rock17cm {
  translation -1.18 -0.18 1.74
  name "rock 17 cm(5)"
}
DEF 台子 Solid {
  translation 3.08 0.12 1.34
  children [
    Shape {
      appearance Appearance {
        material Material {
        }
      }
      geometry Cylinder {
        height 0.18
        radius 0.08
      }
    }
  ]
  boundingObject Cylinder {
    height 0.18
    radius 0.08
  }
  physics Physics {
    mass 99
  }
}
Rock10cm {
  translation -0.95 -0.01 0.73
}
Rock10cm {
  translation -0.95 -0.01 0.73
  name "rock 10 cm(5)"
}
Rock10cm {
  translation -0.78 -0.01 0.83
  name "rock 10 cm(20)"
}
Rock10cm {
  translation -0.59 -0.01 0.73
  name "rock 10 cm(21)"
}
Rock10cm {
  translation -0.88 -0.03 0.65
  name "rock 10 cm(22)"
}
Rock10cm {
  translation -0.14 0.08 -4.32
  rotation 0 1 0 -2.3561953071795863
  name "rock 10 cm(35)"
}
Rock10cm {
  translation -0.31 0.08 -4.08
  rotation 0 1 0 0.523599
  name "rock 10 cm(36)"
}
Rock10cm {
  translation -0.21 0.1 -4.08
  name "rock 10 cm(30)"
}
Rock10cm {
  translation -1.29 -0.02 0.73
  rotation 0 1 0 -0.785395307179586
  name "rock 10 cm(2)"
}
Rock10cm {
  translation -1.16981 0.01 0.850207
  rotation 0 1 0 -0.785395307179586
  name "rock 10 cm(3)"
}
Rock10cm {
  translation -1.26172 -0.01 0.94213
  rotation 0 1 0 -0.785395307179586
  name "rock 10 cm(4)"
}
Rock10cm {
  translation -0.95 -0.04 1.15
  rotation 0 1 0 0.523599
  name "rock 10 cm(1)"
}
Rock10cm {
  translation -0.89 -0.04 1.25392
  rotation 0 1 0 0.523599
  name "rock 10 cm(9)"
}
Rock10cm {
  translation -1.20114 -0.01 1.295
  rotation 0 1 0 0.523599
  name "rock 10 cm(10)"
}
Rock10cm {
  translation -1.29738 -0.01 1.4083
  rotation 0 1 0 0.523599
  name "rock 10 cm(14)"
}
Rock10cm {
  translation -0.725 -0.01 1.5397
  rotation 0 1 0 0.523599
  name "rock 10 cm(11)"
}
Rock10cm {
  translation -0.98722 -0.05 1.42552
  rotation 0 1 0 0.523599
  name "rock 10 cm(12)"
}
Rock10cm {
  translation -0.601172 -0.01 1.21418
  rotation 0 1 0 0.523599
  name "rock 10 cm(7)"
}
Rock10cm {
  translation -0.664732 -0.05 1.42408
  rotation 0 1 0 0.523599
  name "rock 10 cm(13)"
}
Rock10cm {
  translation -0.386172 -0.01 1.58656
  rotation 0 1 0 0.523599
  name "rock 10 cm(8)"
}
Rock10cm {
  translation -0.92284 -0.01 1.67702
  rotation 0 1 0 0.523599
  name "rock 10 cm(6)"
}
Rock10cm {
  translation -1.0781 -0.01 1.6281
  rotation 0 1 0 1.5708
  name "rock 10 cm(19)"
}
Rock10cm {
  translation -1.0597 -0.07 1.85996
  rotation 0 1 0 1.309
  name "rock 10 cm(15)"
}
Rock10cm {
  translation -0.9947 -0.01 1.97254
  rotation 0 1 0 -0.785395307179586
  name "rock 10 cm(16)"
}
Rock10cm {
  translation -0.9297 -0.05 2.08512
  rotation 0 1 0 0.523599
  name "rock 10 cm(17)"
}
Rock10cm {
  translation -0.93078 -0.07 1.84326
  rotation 0 1 0 0.523599
  name "rock 10 cm(18)"
}
ThreeSteps {
  translation 2.19 -0.6 1.18
  increment 0 0.035 0
}
ThreeSteps {
  translation 2.19 -0.48 4.09
  name "three steps(1)"
  increment 0 0.035 0
}
