#VRML_SIM R2021b utf8
WorldInfo {
  basicTimeStep 5
  coordinateSystem "NUE"
}
Viewpoint {
  orientation -0.03875214591284285 0.9786754805131843 0.20172400707262733 2.850117407019356
  position 3.1998694532322793 0.5987176794389281 -6.6696959374204825
  follow "robot(2)"
}
TexturedBackground {
}
Robot {
  translation 2.865010112946373 -0.16453819383354815 -4.688548941205387
  rotation -0.03597775379436228 0.9983359109807836 -0.04506672916998949 1.575232998628209
  children [
    Lidar {
      translation 0 0.07 -0.16
      children [
        HokuyoUtm30lx {
          translation 0 0.03 -0.01
          enablePhysics FALSE
        }
      ]
    }
    GPS {
    }
    InertialUnit {
      translation 0 0.05 0
      name "imu"
    }
    DEF body Group {
      children [
        Shape {
          appearance Appearance {
            material Material {
              diffuseColor 0.666667 0 0.498039
            }
          }
          geometry Box {
            size 0.152 0.09 0.43
          }
        }
        Transform {
          translation 0.132 0 0
          children [
            Shape {
              appearance Appearance {
                material Material {
                  diffuseColor 0 0.333333 0
                }
              }
            }
          ]
        }
        Transform {
          translation -0.132 0 0
        }
        Transform {
          translation 0.184 0 0
        }
        Transform {
          translation -0.184 0 0
        }
      ]
    }
    DEF fr_6 HingeJoint {
      jointParameters HingeJointParameters {
        position 0.2526927863751345
        anchor -0.096 0 0.17
      }
      device [
        PositionSensor {
          name "pos_6"
        }
        RotationalMotor {
          name "motor_6"
          controlPID 15 0 0.5
          maxVelocity 94.2
          maxTorque 21
        }
      ]
      endPoint Solid {
        translation -0.09599941548482116 -3.9309015971350543e-05 0.16998136366372213
        rotation 0.12256002591774184 -0.1228841564920921 0.9848241082194675 1.5861830662302259
        children [
          DEF kuan_1 Shape {
            appearance Appearance {
              material Material {
                diffuseColor 1 0.333333 0
              }
            }
            geometry Cylinder {
              height 0.04
              radius 0.045
            }
          }
          DEF kuan_2 Group {
            children [
              Transform {
                translation 0 0.026 0
                children [
                  Shape {
                    appearance Appearance {
                      material Material {
                        diffuseColor 0.5 0.5 0.5
                      }
                    }
                    geometry Cylinder {
                      height 0.012
                      radius 0.02
                    }
                  }
                ]
              }
              Transform {
                translation 0 0.026 0.05
                children [
                  Shape {
                    appearance Appearance {
                      material Material {
                        diffuseColor 0.5 0.5 0.5
                      }
                    }
                    geometry Box {
                      size 0.03 0.012 0.1
                    }
                  }
                ]
              }
              Transform {
                translation 0 0.026 0.1
                children [
                  Shape {
                    appearance Appearance {
                      material Material {
                        diffuseColor 0.5 0.5 0.5
                      }
                    }
                    geometry Cylinder {
                      height 0.012
                      radius 0.02
                    }
                  }
                ]
              }
            ]
          }
          HingeJoint {
            jointParameters HingeJointParameters {
              position 0.27081380142618894
              axis 0 1 0
              anchor 0 0.03 0.1
            }
            endPoint Solid {
              translation 0 0.03 0.1
              rotation 0 1 0 1.3178138014261398
              children [
                DEF XI Group {
                  children [
                    Transform {
                      translation 0 -0.004 -0.115
                      children [
                        Shape {
                          appearance Appearance {
                            material Material {
                              diffuseColor 0.5 0.5 0.5
                            }
                          }
                          geometry Box {
                            size 0.02 0.01 0.23
                          }
                        }
                      ]
                    }
                    Transform {
                      translation 0 -0.004 -0.23
                      children [
                        DEF foot Shape {
                          appearance Appearance {
                            material Material {
                              diffuseColor 0 0.666667 0
                            }
                          }
                          geometry Sphere {
                            radius 0.015
                          }
                        }
                      ]
                    }
                  ]
                }
                Transform {
                  translation 0 -0.004 -0.23
                  children [
                    TouchSensor {
                      translation 3.0748195070096074e-06 4.8122715590182e-07 5.4893846077597175e-06
                      rotation 0.811157249387431 -0.3804970272723666 -0.44412377666942043 7.87447238280399e-09
                      name "Foot_C"
                      boundingObject USE foot
                      physics Physics {
                      }
                      linearVelocity 1.1918633677789427e-06 -2.31660210855632e-06 -8.92058949076731e-06
                      angularVelocity 1.4832641747295907e-05 2.010193590433343e-06 6.469853923957446e-07
                    }
                  ]
                }
              ]
              name "solid_xi_"
              boundingObject USE XI
              physics Physics {
                density -1
                mass 0.25
              }
              linearVelocity 1.1273690224894881e-06 -2.2103343295221024e-06 -7.869396825854745e-06
              angularVelocity 1.4832620582286227e-05 2.010191240255693e-06 6.469539747226868e-07
            }
          }
        ]
        boundingObject USE kuan_1
        physics Physics {
          density -1
          mass 0.25
        }
        linearVelocity 9.408521190046315e-07 -1.6949026651769116e-06 -5.629605813440852e-06
        angularVelocity 1.4831593124471688e-05 2.0178267698466573e-06 7.361588077548173e-07
      }
    }
    DEF fl_7 HingeJoint {
      jointParameters HingeJointParameters {
        position 0.2526922634376042
        anchor 0.096 0 0.17
      }
      device [
        RotationalMotor {
          name "motor_7"
          controlPID 15 0 0.5
          maxVelocity 94.2
          maxTorque 21
        }
        PositionSensor {
          name "pos_7"
        }
      ]
      endPoint Solid {
        translation 0.09600057359229108 -3.930641722340101e-05 0.16998137280309453
        rotation 0.12256003147353829 -0.12288365977663844 0.9848241695069757 1.58618289507952
        children [
          Transform {
            translation 0 -0.052 0
            children [
              USE kuan_2
            ]
          }
          DEF fl_1 Shape {
            appearance Appearance {
              material Material {
                diffuseColor 1 0.333333 0
              }
            }
            geometry Cylinder {
              height 0.04
              radius 0.045
            }
          }
          HingeJoint {
            jointParameters HingeJointParameters {
              position 0.270783955107474
              axis 0 1 0
              anchor 0 -0.052 0.1
            }
            endPoint Solid {
              translation 0 -0.02200000000000006 0.1
              rotation 0 1 0 1.3177839551074235
              children [
                TouchSensor {
                  translation 3.712727832283491e-06 -0.003999518031288396 -0.22999304246568109
                  rotation 0.8716118221545139 -0.111491855087591 -0.47734934558414926 7.3317427142240164e-09
                  name "Foot_D"
                  boundingObject USE foot
                  physics Physics {
                  }
                  linearVelocity 4.903205752398908e-07 1.1718368225704042e-06 -9.20101457264032e-06
                  angularVelocity 1.4829959865358596e-05 1.957576533323008e-06 7.382046460857088e-09
                }
                USE XI
              ]
              name "solid_fl"
              boundingObject USE XI
              physics Physics {
                density -1
                mass 0.25
              }
              linearVelocity 4.942513590785902e-07 1.2853585187144798e-06 -8.150943588508549e-06
              angularVelocity 1.4829943620895851e-05 1.9575970461365995e-06 7.632736049623526e-09
            }
          }
        ]
        name "solid(1)"
        boundingObject USE fl_1
        physics Physics {
          density -1
          mass 0.25
        }
        linearVelocity 5.278432869637584e-07 1.0655040432805407e-06 -5.852566393649284e-06
        angularVelocity 1.4829998276389622e-05 2.0165751740798572e-06 7.188000092038029e-07
      }
    }
    DEF rl_3 HingeJoint {
      jointParameters HingeJointParameters {
        position 0.2526924569473431
        anchor 0.096 0 -0.17
      }
      device [
        RotationalMotor {
          name "motor_3"
          controlPID 15 0 0.5
          maxVelocity 94.2
          maxTorque 21
        }
        PositionSensor {
          name "pos_3"
        }
      ]
      endPoint Solid {
        translation 0.09600057031346965 -3.959061700139379e-05 -0.17001899441883286
        rotation 0.12256013318473913 -0.12288374493840126 0.9848241462228944 1.5861829048322635
        children [
          DEF rl_1 Shape {
            appearance Appearance {
              material Material {
                diffuseColor 1 0.333333 0
              }
            }
            geometry Cylinder {
              height 0.04
              radius 0.045
            }
          }
          Transform {
            translation 0 -0.052 0
            children [
              USE kuan_2
            ]
          }
          HingeJoint {
            jointParameters HingeJointParameters {
              position 0.27079364771339576
              axis 0 1 0
              anchor 0 -0.06 0.1
            }
            endPoint Solid {
              translation 0 -0.022000000000048148 0.1
              rotation 0 1 0 1.3177936477133751
              children [
                TouchSensor {
                  translation 3.3489112114537534e-06 -0.003999592729273971 -0.22999370316445766
                  rotation 0.8660068800848937 -0.15844132087527338 -0.47426620318648827 6.248760139361142e-09
                  name "Foot_B"
                  boundingObject USE foot
                  physics Physics {
                  }
                  linearVelocity 7.426759488365406e-07 8.777523692134707e-07 -8.51034782741764e-06
                  angularVelocity 1.4840494968731648e-05 2.040183450120955e-06 1.0269815845470691e-06
                }
                USE XI
              ]
              name "rl_solid"
              boundingObject USE XI
              physics Physics {
                density -1
                mass 0.25
              }
              linearVelocity 6.510084319329859e-07 1.0327648096719606e-06 -7.450781754383417e-06
              angularVelocity 1.4840298569784488e-05 2.0401848090937333e-06 1.0269771304190684e-06
            }
          }
        ]
        name "solid(2)"
        boundingObject USE rl_1
        physics Physics {
          density -1
          mass 0.25
        }
        linearVelocity 5.42347115661812e-07 8.432482424947097e-07 -5.138630280037137e-06
        angularVelocity 1.4834964838682023e-05 2.017858514305469e-06 7.323164470195258e-07
      }
    }
    DEF rr_2 HingeJoint {
      jointParameters HingeJointParameters {
        position 0.2526927190839552
        anchor -0.096 0 -0.17
      }
      device [
        PositionSensor {
          name "pos_2"
        }
        RotationalMotor {
          name "motor_2"
          controlPID 15 0 0.5
          maxVelocity 94.2
          maxTorque 21
        }
      ]
      endPoint Solid {
        translation -0.09599945582510272 -3.9592601024048547e-05 -0.17001900367294864
        rotation 0.12256009954590191 -0.1228840513911128 0.9848241121708003 1.5861827379091753
        children [
          DEF rr_1 Shape {
            appearance Appearance {
              material Material {
                diffuseColor 1 0.333333 0
              }
            }
            geometry Cylinder {
              height 0.04
              radius 0.045
            }
          }
          Transform {
            children [
              USE kuan_2
            ]
          }
          HingeJoint {
            jointParameters HingeJointParameters {
              position 0.27084305460609515
              axis 0 1 0
              anchor 0 0 0.1
            }
            endPoint Solid {
              translation 0 0.030000000000123386 0.1
              rotation 0 1 0 1.3178430546060562
              children [
                TouchSensor {
                  translation 2.434948006335702e-06 -0.003999592884578185 -0.2299949870018776
                  rotation 0.8423982497861443 0.2782882522365112 -0.461433459368075 6.428581860089975e-09
                  name "Foot_A"
                  boundingObject USE foot
                  physics Physics {
                  }
                  linearVelocity 1.4314491483963525e-06 -2.6085060402189563e-06 -8.229109754086286e-06
                  angularVelocity 1.4839260738181205e-05 2.0881084627690597e-06 1.613670279170797e-06
                }
                USE XI
              ]
              name "rr_solid"
              boundingObject USE XI
              physics Physics {
                density -1
                mass 0.25
              }
              linearVelocity 1.2762523981452112e-06 -2.4630404539394104e-06 -7.168567297761168e-06
              angularVelocity 1.4839060406432145e-05 2.0880879781861365e-06 1.6133960199006511e-06
            }
          }
        ]
        name "solid(3)"
        boundingObject USE rr_1
        physics Physics {
          density -1
          mass 0.25
        }
        linearVelocity 9.54719071426524e-07 -1.9189514915751714e-06 -4.9154465290679465e-06
        angularVelocity 1.4834001227126877e-05 2.0190012073513394e-06 7.488019599860363e-07
      }
    }
    DEF fr_5 HingeJoint {
      jointParameters HingeJointParameters {
        position -0.2526656593236784
        anchor -0.16 0 0.17
      }
      device [
        PositionSensor {
          name "pos_5"
        }
        RotationalMotor {
          name "motor_5"
          controlPID 15 0 0.5
          maxVelocity 94.2
          maxTorque 21
        }
      ]
      endPoint Solid {
        translation -0.16000057987340388 -4.6253333120948915e-05 0.17002434831037982
        rotation -0.12713113873509976 0.1274551447562791 0.9836629807200598 1.5873787944257816
        children [
          USE kuan_1
          DEF kuan_3 Group {
            children [
              Transform {
                translation 0 -0.026 0
                children [
                  Shape {
                    appearance Appearance {
                      material Material {
                      }
                    }
                    geometry Cylinder {
                      height 0.012
                      radius 0.02
                    }
                  }
                ]
              }
              Transform {
                translation 0 -0.026 -0.05
                children [
                  Shape {
                    appearance Appearance {
                      material Material {
                      }
                    }
                    geometry Box {
                      size 0.02 0.012 0.1
                    }
                  }
                ]
              }
              Transform {
                translation 0 -0.026 -0.1
                children [
                  Shape {
                    appearance Appearance {
                      material Material {
                      }
                    }
                    geometry Cylinder {
                      height 0.012
                      radius 0.02
                    }
                  }
                ]
              }
            ]
          }
          HingeJoint {
            jointParameters HingeJointParameters {
              position -0.2709060202908724
              axis 0 1 0
              anchor 0 -0.026 -0.1
            }
            endPoint Solid {
              translation 0 -0.026 -0.1
              rotation 0 -0.9999999999999999 0 1.3179060202908264
              children [
                DEF xi_2 Transform {
                  translation 0 0 0.1
                  children [
                    Shape {
                      appearance Appearance {
                        material Material {
                        }
                      }
                      geometry Box {
                        size 0.02 0.012 0.2
                      }
                    }
                  ]
                }
                HingeJoint {
                  jointParameters HingeJointParameters {
                    position 0.03637648116745104
                    axis 0 1 0
                    anchor 0 0 0.2
                  }
                  endPoint SolidReference {
                    solidName "solid_xi_"
                  }
                }
              ]
              name "solid(6)"
              boundingObject USE xi_2
              physics Physics {
                density -1
                mass 0.25
              }
              linearVelocity 1.104654583752307e-06 -2.4188235215216737e-06 -7.1454633382933565e-06
              angularVelocity 1.4833377231411668e-05 2.031288696730884e-06 9.039277079185234e-07
            }
          }
        ]
        name "solid(6)"
        boundingObject USE kuan_1
        physics Physics {
          density -1
          mass 0.25
        }
        linearVelocity 1.0461642069969912e-06 -2.649708677529006e-06 -5.549509035489009e-06
        angularVelocity 1.4831980099300495e-05 2.0171471983239647e-06 7.321368886402895e-07
      }
    }
    DEF fl_8 HingeJoint {
      jointParameters HingeJointParameters {
        position -0.2526652295778104
        anchor 0.16 0 0.17
      }
      device [
        RotationalMotor {
          name "motor_8"
          controlPID 15 0 0.5
          maxVelocity 94.2
          maxTorque 21
        }
        PositionSensor {
          name "pos_8"
        }
      ]
      endPoint Solid {
        translation 0.15999943105918057 -4.6239885478292946e-05 0.17002433507311143
        rotation -0.12713065057281533 0.12745515373858796 0.983663042647433 1.5873792244249634
        children [
          USE kuan_1
          Transform {
            translation 0 0.052 0
            children [
              USE kuan_3
            ]
          }
          HingeJoint {
            jointParameters HingeJointParameters {
              position -0.2708966360380919
              axis 0 1 0
              anchor 0 0 -0.1
            }
            endPoint Solid {
              translation 0 0.025999999999876306 -0.1
              rotation 0 -1 0 1.3178966360380615
              children [
                USE xi_2
                HingeJoint {
                  jointParameters HingeJointParameters {
                    position 0.03633829734986696
                    axis 0 1 0
                    anchor 0 0 0.2
                  }
                  endPoint SolidReference {
                    solidName "solid_fl"
                  }
                }
              ]
              boundingObject USE xi_2
              physics Physics {
                density -1
                mass 0.25
              }
              linearVelocity 4.863457809634042e-07 1.4953942497530903e-06 -7.461612926785711e-06
              angularVelocity 1.482904737082105e-05 1.9456172424834908e-06 -1.418853833672054e-07
            }
          }
        ]
        name "solid(4)"
        boundingObject USE kuan_1
        physics Physics {
          density -1
          mass 0.25
        }
        linearVelocity 4.204195678347844e-07 2.079893272943778e-06 -5.932307679253901e-06
        angularVelocity 1.4831448813586357e-05 2.0159995693041897e-06 7.226224431120494e-07
      }
    }
    DEF rl_4 HingeJoint {
      jointParameters HingeJointParameters {
        position -0.2526655164466989
        anchor 0.16 0 -0.17
      }
      device [
        RotationalMotor {
          name "motor_4"
          controlPID 15 0 0.5
          maxVelocity 94.2
          maxTorque 21
        }
        PositionSensor {
          name "pos_4"
        }
      ]
      endPoint Solid {
        translation 0.15999943450623233 -4.664620309452426e-05 -0.1699752618436136
        rotation -0.12713078400309194 0.12745529430127267 0.9836630071896245 1.5873792847469923
        children [
          USE kuan_1
          Transform {
            translation 0 0.052 0
            children [
              USE kuan_3
            ]
          }
          HingeJoint {
            jointParameters HingeJointParameters {
              position -0.27089312216773787
              axis 0 1 0
              anchor 0 0 -0.1
            }
            endPoint Solid {
              translation 0 0.025999999999985996 -0.1
              rotation 0 -1 0 1.3178931221677284
              children [
                USE xi_2
                HingeJoint {
                  jointParameters HingeJointParameters {
                    position 0.03635233800654698
                    axis 0 1 0
                    anchor 0 0 0.2
                  }
                  endPoint SolidReference {
                    solidName "rl_solid"
                  }
                }
              ]
              boundingObject USE xi_2
              physics Physics {
                density -1
                mass 0.25
              }
              linearVelocity 5.995519324386578e-07 1.2064206196260585e-06 -6.748496591427733e-06
              angularVelocity 1.4838432023869833e-05 2.0171660385784983e-06 7.327276269441269e-07
            }
          }
        ]
        name "solid(5)"
        boundingObject USE kuan_1
        physics Physics {
          density -1
          mass 0.25
        }
        linearVelocity 4.380541676418659e-07 1.7844485406559585e-06 -5.207680579023543e-06
        angularVelocity 1.4834781100065757e-05 2.0167396006324924e-06 7.351530127336224e-07
      }
    }
    DEF rr_1 HingeJoint {
      jointParameters HingeJointParameters {
        position -0.25266619819809655
        anchor -0.16 0 -0.17
      }
      device [
        RotationalMotor {
          name "motor_1"
          controlPID 15 0 0.5
          maxVelocity 94.2
          maxTorque 21
        }
        PositionSensor {
          name "pos_1"
        }
      ]
      endPoint Solid {
        translation -0.1600005393708559 -4.666009778444528e-05 -0.1699752481436523
        rotation -0.1271314495863885 0.12745534065776581 0.9836629151614268 1.5873789596691834
        children [
          Transform {
            translation 0 -0.052 -0.1
            children [
              USE kuan_2
            ]
          }
          USE kuan_1
          HingeJoint {
            jointParameters HingeJointParameters {
              position -0.27088560519846133
              axis 0 1 0
              anchor 0 0 -0.1
            }
            endPoint Solid {
              translation 0 -0.03799999999992404 -0.1
              rotation 0 -1 0 1.3178856051984327
              children [
                USE xi_2
                HingeJoint {
                  jointParameters HingeJointParameters {
                    position 0.0363930496112241
                    axis 0 1 0
                    anchor 0 0 0.2
                  }
                  endPoint SolidReference {
                    solidName "rr_solid"
                  }
                }
              ]
              boundingObject USE xi_2
              physics Physics {
                density -1
                mass 0.25
              }
              linearVelocity 1.1886916722758655e-06 -2.5288095170328263e-06 -6.446362250064619e-06
              angularVelocity 1.4838932270176797e-05 2.098358434160395e-06 1.7346820345985068e-06
            }
          }
        ]
        name "solid(7)"
        boundingObject USE kuan_1
        physics Physics {
          density -1
          mass 0.25
        }
        linearVelocity 1.0628573053850233e-06 -2.9434663704552832e-06 -4.82498140392168e-06
        angularVelocity 1.4833318775424755e-05 2.0173272713272703e-06 7.444121804480721e-07
      }
    }
  ]
  name "robot(2)"
  boundingObject USE body
  physics Physics {
    density -1
    mass 5
  }
  controller "<extern>"
  linearVelocity 7.406923352446527e-07 -4.2865621458787475e-07 -5.37398244860815e-06
  angularVelocity 1.483083284361417e-05 2.0171247550901097e-06 7.335587892727833e-07
}
Ramp30deg {
  translation 0.623055 -1.15717 -4.69
  rotation 0 0 1 -0.261795307179586
}
TexturedBackgroundLight {
}
UnevenTerrain {
  translation 0 -3.6 8.94
}
Rock17cm {
  translation -0.68 -0.17 0.67
}
Rock17cm {
  translation -0.8 -0.17 0.49
  name "rock 17 cm(12)"
}
Rock17cm {
  translation -0.68 -0.15 1.64
  name "rock 17 cm(8)"
}
Rock17cm {
  translation -0.68 -0.15 1.96
  rotation 0 1 0 1.0472
  name "rock 17 cm(20)"
}
Rock17cm {
  translation -0.93 -0.13 0.88
  rotation 2.31518e-08 -1 -9.58979e-09 -0.785395307179586
  name "rock 17 cm(3)"
}
Rock17cm {
  translation -1.12797 -0.15 0.682012
  rotation 0 1 0 0.785398
  name "rock 17 cm(11)"
}
Rock17cm {
  translation -0.68 -0.15 0.99
  rotation 0 1 0 0.785398
  name "rock 17 cm(2)"
}
Rock17cm {
  translation -0.453728 -0.16 1.11726
  rotation 0 1 0 1.309
  name "rock 17 cm(24)"
}
Rock17cm {
  translation -0.85867 -0.16 1.0838
  rotation 0 1 0 1.8326
  name "rock 17 cm(23)"
}
Rock17cm {
  translation -0.453728 -0.15 0.763728
  rotation 0 1 0 0.785398
  name "rock 17 cm(7)"
}
Rock17cm {
  translation -0.835562 -0.16 1.40006
  rotation 0 1 0 0.785398
  name "rock 17 cm(6)"
}
Rock17cm {
  translation -1.15374 -0.16 1.46369
  rotation 0 1 0 0.785398
  name "rock 17 cm(4)"
}
Rock17cm {
  translation -1.26686 -0.19 1.57681
  rotation 0 1 0 0.785398
  name "rock 17 cm(14)"
}
Rock17cm {
  translation -1.18 -0.16 1.08
  name "rock 17 cm(1)"
}
Rock17cm {
  translation -1.06 -0.17 1.26
  name "rock 17 cm(10)"
}
Rock17cm {
  translation -0.46 -0.18 1.34
  name "rock 17 cm(9)"
}
Rock17cm {
  translation -0.49 -0.16 1.57
  name "rock 17 cm(13)"
}
Rock17cm {
  translation -0.79 -0.22 1.86
  name "rock 17 cm(15)"
}
Rock17cm {
  translation -0.45 -0.18 1.86
  rotation 0 1 0 -0.785395307179586
  name "rock 17 cm(16)"
}
Rock17cm {
  translation -0.79 -0.18 2.12
  rotation 0 1 0 0.523599
  name "rock 17 cm(17)"
}
Rock17cm {
  translation -0.56 -0.19 2.27
  rotation 0 1 0 1.309
  name "rock 17 cm(18)"
}
Rock17cm {
  translation -1.04297 -0.2 2.14055
  rotation 0 1 0 -0.523595307179586
  name "rock 17 cm(19)"
}
Rock17cm {
  translation -1.26702 -0.18 2.04941
  rotation 0 1 0 2.618
  name "rock 17 cm(21)"
}
Rock17cm {
  translation -0.913809 -0.21 2.39262
  rotation 0 1 0 1.309
  name "rock 17 cm(22)"
}
Rock17cm {
  translation -1.18 -0.18 1.74
  name "rock 17 cm(5)"
}
DEF 台子 Solid {
  translation 3.08 0.14196503125000007 1.34
  rotation 0.9906469728117409 0.0007180575161771323 0.1364480108038863 9.40669061467399e-15
  children [
    Shape {
      appearance Appearance {
        material Material {
        }
      }
      geometry Cylinder {
        height 0.18
        radius 0.08
      }
    }
  ]
  boundingObject Cylinder {
    height 0.18
    radius 0.08
  }
  physics Physics {
    mass 99
  }
  linearVelocity -2.439774781616132e-16 -9.029636269932728e-16 1.9828732647842537e-15
  angularVelocity 2.280302659743921e-14 -1.4861824551251948e-17 2.8009855025779168e-15
}
Rock10cm {
  translation -0.95 -0.01 0.73
}
Rock10cm {
  translation -0.95 -0.01 0.73
  name "rock 10 cm(5)"
}
Rock10cm {
  translation -0.78 -0.01 0.83
  name "rock 10 cm(20)"
}
Rock10cm {
  translation -0.59 -0.01 0.73
  name "rock 10 cm(21)"
}
Rock10cm {
  translation -0.88 -0.03 0.65
  name "rock 10 cm(22)"
}
Rock10cm {
  translation -0.14 0.08 -4.32
  rotation 0 1 0 -2.3561953071795863
  name "rock 10 cm(35)"
}
Rock10cm {
  translation -0.31 0.08 -4.08
  rotation 0 1 0 0.523599
  name "rock 10 cm(36)"
}
Rock10cm {
  translation -0.21 0.1 -4.08
  name "rock 10 cm(30)"
}
Rock10cm {
  translation -1.29 -0.02 0.73
  rotation 0 1 0 -0.785395307179586
  name "rock 10 cm(2)"
}
Rock10cm {
  translation -1.16981 0.01 0.850207
  rotation 0 1 0 -0.785395307179586
  name "rock 10 cm(3)"
}
Rock10cm {
  translation -1.26172 -0.01 0.94213
  rotation 0 1 0 -0.785395307179586
  name "rock 10 cm(4)"
}
Rock10cm {
  translation -0.95 -0.04 1.15
  rotation 0 1 0 0.523599
  name "rock 10 cm(1)"
}
Rock10cm {
  translation -0.89 -0.04 1.25392
  rotation 0 1 0 0.523599
  name "rock 10 cm(9)"
}
Rock10cm {
  translation -1.20114 -0.01 1.295
  rotation 0 1 0 0.523599
  name "rock 10 cm(10)"
}
Rock10cm {
  translation -1.29738 -0.01 1.4083
  rotation 0 1 0 0.523599
  name "rock 10 cm(14)"
}
Rock10cm {
  translation -0.725 -0.01 1.5397
  rotation 0 1 0 0.523599
  name "rock 10 cm(11)"
}
Rock10cm {
  translation -0.98722 -0.05 1.42552
  rotation 0 1 0 0.523599
  name "rock 10 cm(12)"
}
Rock10cm {
  translation -0.601172 -0.01 1.21418
  rotation 0 1 0 0.523599
  name "rock 10 cm(7)"
}
Rock10cm {
  translation -0.664732 -0.05 1.42408
  rotation 0 1 0 0.523599
  name "rock 10 cm(13)"
}
Rock10cm {
  translation -0.386172 -0.01 1.58656
  rotation 0 1 0 0.523599
  name "rock 10 cm(8)"
}
Rock10cm {
  translation -0.92284 -0.01 1.67702
  rotation 0 1 0 0.523599
  name "rock 10 cm(6)"
}
Rock10cm {
  translation -1.0781 -0.01 1.6281
  rotation 0 1 0 1.5708
  name "rock 10 cm(19)"
}
Rock10cm {
  translation -1.0597 -0.07 1.85996
  rotation 0 1 0 1.309
  name "rock 10 cm(15)"
}
Rock10cm {
  translation -0.9947 -0.01 1.97254
  rotation 0 1 0 -0.785395307179586
  name "rock 10 cm(16)"
}
Rock10cm {
  translation -0.9297 -0.05 2.08512
  rotation 0 1 0 0.523599
  name "rock 10 cm(17)"
}
Rock10cm {
  translation -0.93078 -0.07 1.84326
  rotation 0 1 0 0.523599
  name "rock 10 cm(18)"
}
ThreeSteps {
  translation 2.19 -0.6 1.18
  increment 0 0.035 0
}
ThreeSteps {
  translation 2.19 -0.48 4.09
  name "three steps(1)"
  increment 0 0.035 0
}
