#VRML_SIM R2021b utf8
WorldInfo {
  basicTimeStep 1
  coordinateSystem "NUE"
  contactProperties [
    ContactProperties {
    }
  ]
}
Viewpoint {
  orientation -0.851083934903638 0.2007945539841343 0.4851161539665036 0.08545855217454601
  position 0.0661753465181188 0.22579577151158642 0.9549944713871832
  follow "robot"
}
TexturedBackgroundLight {
}
UnevenTerrain {
  translation 0 -3.29 0
  rotation 0 1 0 1.8326
  size 6 5 6
  appearance SandyGround {
    colorOverride 0.4 0.2 0.1
    textureTransform TextureTransform {
      scale 50 50
    }
  }
}
TexturedBackground {
}
Robot {
  translation 0 0.2 0
  children [
    InertialUnit {
    }
    DEF body Shape {
      appearance Appearance {
        material Material {
          diffuseColor 0.66667 0 0
          specularColor 0 0 0.498039
        }
      }
      geometry Box {
        size 0.26 0.05 0.18
      }
    }
    Transform {
      translation -0.12 0.02 0
      scale 0.5 0.5 0.5
      children [
        Kinect {
          rotation 0 1 0 1.5708
          width 160
          height 95
        }
      ]
    }
    Transform {
      translation -0.06 0.02 0.05
      rotation 0 0 1 -1.5707953071795862
      children [
        Shape {
          geometry Capsule {
            height 0.04
            radius 0.02
          }
        }
      ]
    }
    Transform {
      translation -0.06 0.02 -0.05
      rotation 0 0 1 -1.5707953071795862
      children [
        Shape {
          geometry Capsule {
            height 0.04
            radius 0.02
          }
        }
      ]
    }
    Transform {
      translation 0.06 0.02 0.05
      rotation 0 0 1 -1.5707953071795862
      children [
        Shape {
          geometry Capsule {
            height 0.04
            radius 0.02
          }
        }
      ]
    }
    Transform {
      translation 0.06 0.02 -0.05
      rotation 0 0 1 -1.5707953071795862
      children [
        Shape {
          geometry Capsule {
            height 0.04
            radius 0.02
          }
        }
      ]
    }
    DEF rf_1_1 HingeJoint {
      jointParameters HingeJointParameters {
        axis 0 0 1
        anchor 0.07 0 0.1
      }
      device [
        RotationalMotor {
          name "motor_rf_1"
          maxTorque 4
        }
        PositionSensor {
          name "sensor_rf_1"
        }
      ]
      endPoint DEF rf_1_1 Solid {
        translation 0.07 0 0.1
        rotation 0.04174546001603349 -0.010636870066013984 -0.9990716558702125 0.014455616389482853
        children [
          DEF rf_1_2 HingeJoint {
            jointParameters HingeJointParameters {
              axis 0 0 1
              anchor -0.04 0 0
            }
            endPoint DEF rf_1_2 Solid {
              translation -0.04 0 0
              rotation 0 0 1 0
              children [
                DEF foot_rf TouchSensor {
                  translation 0.061 -0.106 -7.39255e-05
                  children [
                    DEF foot_rf Shape {
                      appearance Appearance {
                        material Material {
                          diffuseColor 0 0.666667 0
                        }
                      }
                      geometry Sphere {
                        radius 0.007
                        subdivision 3
                      }
                    }
                  ]
                  name "foot_rf"
                  boundingObject USE foot_rf
                  physics Physics {
                    density -1
                    mass 0.1
                  }
                  lookupTable [
                    0 0 0
                    1000 1000 0
                  ]
                }
                Transform {
                  translation 0.03 -0.052 0
                  rotation 0 0 -1 -0.5235996938995747
                  children [
                    DEF rf_1_2 Shape {
                      appearance Appearance {
                        material Material {
                          diffuseColor 1 1 0
                          emissiveColor 0.3333 0 0
                        }
                      }
                      geometry Capsule {
                        height 0.12
                        radius 0.005
                      }
                    }
                  ]
                }
              ]
              name "rf_1_2"
              boundingObject Transform {
                translation 0.03 -0.052 0
                rotation 0 0 -1 -0.5235996938995747
                children [
                  USE rf_1_2
                ]
              }
              physics Physics {
                mass 0.1
              }
            }
          }
          Transform {
            translation -0.02 0 0
            rotation 0 0 1 1.5708003061004252
            children [
              DEF rf_1_1 Shape {
                appearance Appearance {
                  material Material {
                    diffuseColor 1 1 0
                    emissiveColor 0.33333 0 0
                  }
                }
                geometry Capsule {
                  height 0.04
                  radius 0.005
                }
              }
            ]
          }
        ]
        name "rf_1_1"
        boundingObject Transform {
          translation -0.02 0 0
          rotation 0 0 1 1.5707996938995747
          children [
            USE rf_1_1
          ]
        }
        physics Physics {
          mass 0.1
        }
      }
    }
    DEF rf_2_1 HingeJoint {
      jointParameters HingeJointParameters {
        axis 0 0 1
        anchor 0.11 0 0.1
      }
      device [
        RotationalMotor {
          name "motor_rf_2"
          maxTorque 4
        }
        PositionSensor {
          name "sensor_rf_2"
        }
      ]
      endPoint DEF rf_2_1 Solid {
        translation 0.11 0 0.1
        rotation -7.678860552588828e-08 1.4044717217909583e-07 -0.9999999999999873 3.141592696588167
        children [
          DEF rf_2_2 HingeJoint {
            jointParameters HingeJointParameters {
              axis 0 0 1
              anchor -0.04 0 0
            }
            endPoint DEF rf_2_2 Solid {
              translation -0.04 0 0
              rotation -4.741002763294896e-07 -9.414458917477852e-07 0.9999999999994444 0.003503345219996585
              children [
                DEF rf_2_1 HingeJoint {
                  jointParameters HingeJointParameters {
                    axis 0 0 1
                    anchor 0.061 0.106 0
                  }
                  endPoint SolidReference {
                    solidName "rf_1_2"
                  }
                }
                Transform {
                  translation 0.031 0.053 0
                  rotation 0 0 1 -0.5235996938995747
                  children [
                    DEF rf_2_2 Shape {
                      appearance Appearance {
                        material Material {
                          diffuseColor 1 1 0
                          emissiveColor 0.333333 0 0
                        }
                      }
                      geometry Capsule {
                        height 0.12
                        radius 0.005
                      }
                    }
                  ]
                }
              ]
              name "rf_2_2"
              boundingObject Transform {
                translation 0.031 0.053 0
                rotation 0 0 1 -0.524
                children [
                  USE rf_2_2
                ]
              }
              physics Physics {
                mass 0.2
              }
            }
          }
          Transform {
            translation -0.02 0 0
            rotation 0 0 1 1.5707996938995747
            children [
              DEF rf_2_1 Shape {
                appearance Appearance {
                  material Material {
                    diffuseColor 1 1 0
                    emissiveColor 0.3333 0 0
                  }
                }
                geometry Capsule {
                  height 0.04
                  radius 0.005
                }
              }
            ]
          }
        ]
        name "rf_2_1"
        boundingObject Transform {
          translation -0.02 0 0
          rotation 0 0 1 1.5707996938995747
          children [
            USE rf_2_1
          ]
        }
        physics Physics {
          mass 0.1
        }
      }
    }
    DEF rr_1_1 HingeJoint {
      jointParameters HingeJointParameters {
        axis 0 0 1
        anchor -0.11 0 0.1
      }
      device [
        RotationalMotor {
          name "motor_rr_1"
          maxTorque 4
        }
        PositionSensor {
          name "sensor_rr_1"
        }
      ]
      endPoint DEF rr_1_1 Solid {
        translation -0.11 0 0.1
        rotation 0.9688214609875081 -0.2477599175107461 -2.2579939143941994e-06 0.0006221605895979143
        children [
          DEF rr_1_2 HingeJoint {
            jointParameters HingeJointParameters {
              axis 0 0 1
              anchor -0.04 0 0
            }
            endPoint DEF rr_1_2 Solid {
              translation -0.04 0 0
              rotation 0 0 1 0
              children [
                DEF foot_rr TouchSensor {
                  translation 0.06 -0.104 -7.76809e-05
                  rotation -0.8267781492407786 -0.19855884575675528 -0.5263195575976044 -4.9755755071601016e-12
                  children [
                    DEF foot_rr Shape {
                      appearance Appearance {
                        material Material {
                          diffuseColor 0 0.666667 0
                        }
                      }
                      geometry Sphere {
                        radius 0.007
                        subdivision 3
                      }
                    }
                  ]
                  name "foot_rr"
                  boundingObject USE foot_rr
                  physics Physics {
                    density -1
                    mass 0.1
                  }
                  lookupTable [
                    0 0 0
                    1000 1000 0
                  ]
                }
                Transform {
                  translation 0.03 -0.052 0
                  rotation 0 0 -1 -0.5235996938995747
                  children [
                    DEF rr_1_2 Shape {
                      appearance Appearance {
                        material Material {
                          diffuseColor 1 1 0
                          emissiveColor 0.3333 0 0
                        }
                      }
                      geometry Capsule {
                        height 0.12
                        radius 0.005
                      }
                    }
                  ]
                }
              ]
              name "rr_1_2"
              boundingObject Transform {
                translation 0.03 -0.052 0
                rotation 0 0 -1 -0.5235996938995747
                children [
                  USE rr_1_2
                ]
              }
              physics Physics {
                mass 0.1
              }
            }
          }
          Transform {
            translation -0.02 0 0
            rotation 0 0 1 1.5708003061004252
            children [
              DEF rr_1_1 Shape {
                appearance Appearance {
                  material Material {
                    diffuseColor 1 1 0
                    emissiveColor 0.33333 0 0
                  }
                }
                geometry Capsule {
                  height 0.04
                  radius 0.005
                }
              }
            ]
          }
        ]
        name "rr_1_1"
        boundingObject Transform {
          translation -0.02 0 0
          rotation 0 0 1 1.5707996938995747
          children [
            USE rr_1_1
          ]
        }
        physics Physics {
          mass 0.1
        }
      }
    }
    DEF rr_2_1 HingeJoint {
      jointParameters HingeJointParameters {
        axis 0 0 1
        anchor -0.07 0 0.1
      }
      device [
        RotationalMotor {
          name "motor_rr_2"
          maxTorque 4
        }
        PositionSensor {
          name "sensor_rr_2"
        }
      ]
      endPoint DEF rr_2_1 Solid {
        translation -0.07 0 0.1
        rotation -5.512114034712035e-08 1.8147208225302397e-07 -0.9999999999999821 3.141592776972455
        children [
          DEF rr_2_2 HingeJoint {
            jointParameters HingeJointParameters {
              axis 0 0 1
              anchor -0.04 0 0
            }
            endPoint DEF rr_2_2 Solid {
              translation -0.04 0 0
              rotation 8.82292694832495e-08 -1.528180000000003e-06 0.9999999999988285 0.0035033452226585775
              children [
                DEF rr_2_1 HingeJoint {
                  jointParameters HingeJointParameters {
                    position -3.5598732463899223
                    axis 0 0 1
                    anchor 0.06 0.104 0
                  }
                  endPoint SolidReference {
                    solidName "rr_1_2"
                  }
                }
                Transform {
                  translation 0.031 0.053 0
                  rotation 0 0 1 2.59
                  children [
                    DEF rr_2_2 Shape {
                      appearance Appearance {
                        material Material {
                          diffuseColor 1 1 0
                          emissiveColor 0.333333 0 0
                        }
                      }
                      geometry Capsule {
                        height 0.12
                        radius 0.005
                      }
                    }
                  ]
                }
              ]
              name "rf_2_2"
              boundingObject Transform {
                translation 0.031 0.053 0
                rotation 0 0 1 2.59
                children [
                  USE rr_2_2
                ]
              }
              physics Physics {
                mass 0.2
              }
            }
          }
          Transform {
            translation -0.02 0 0
            rotation 0 0 1 1.5707996938995747
            children [
              DEF rr_2_1 Shape {
                appearance Appearance {
                  material Material {
                    diffuseColor 1 1 0
                    emissiveColor 0.3333 0 0
                  }
                }
                geometry Capsule {
                  height 0.04
                  radius 0.005
                }
              }
            ]
          }
        ]
        name "rr_2_1"
        boundingObject Transform {
          translation -0.02 0 0
          rotation 0 0 1 1.5707996938995747
          children [
            USE rr_2_1
          ]
        }
        physics Physics {
          mass 0.1
        }
      }
    }
    DEF lf_1_1 HingeJoint {
      jointParameters HingeJointParameters {
        axis 0 0 1
        anchor 0.07 0 0.1
      }
      device [
        RotationalMotor {
          name "motor_lf_1"
          maxTorque 4
        }
        PositionSensor {
          name "sensor_lf_1"
        }
      ]
      endPoint DEF rf_1_1 Solid {
        translation 0.07 0.000131379 -0.1
        rotation 0.9687824454460247 -0.2479124146976393 8.963484889969044e-05 0.0006219552467285193
        children [
          DEF lf_1_2 HingeJoint {
            jointParameters HingeJointParameters {
              axis 0 0 1
              anchor -0.04 0 0
            }
            endPoint DEF lf_1_2 Solid {
              translation -0.04 0 0
              rotation -2.9919426346949596e-05 8.365884967017789e-05 -0.9999999960530125 4.87364932874634e-05
              children [
                DEF foot_lf TouchSensor {
                  translation 0.06 -0.104 0.000184646
                  rotation 0.4989966919345071 -0.038715638538197684 0.8657386446099066 1.4484576216756613e-09
                  children [
                    DEF foot_lf Shape {
                      appearance Appearance {
                        material Material {
                          diffuseColor 0 0.666667 0
                        }
                      }
                      geometry Sphere {
                        radius 0.007
                        subdivision 3
                      }
                    }
                  ]
                  name "foot_lf"
                  boundingObject USE foot_lf
                  physics Physics {
                    density -1
                    mass 0.1
                  }
                  lookupTable [
                    0 0 0
                    1000 1000 0
                  ]
                }
                Transform {
                  translation 0.03 -0.052 0
                  rotation 0 0 -1 -0.5235996938995747
                  children [
                    DEF lf_1_2 Shape {
                      appearance Appearance {
                        material Material {
                          diffuseColor 1 1 0
                          emissiveColor 0.3333 0 0
                        }
                      }
                      geometry Capsule {
                        height 0.12
                        radius 0.005
                      }
                    }
                  ]
                }
              ]
              name "lf_1_2"
              boundingObject Transform {
                translation 0.03 -0.052 0
                rotation 0 0 -1 -0.5235996938995747
                children [
                  USE lf_1_2
                ]
              }
              physics Physics {
                mass 0.1
              }
            }
          }
          Transform {
            translation -0.02 0 0
            rotation 0 0 1 1.5708003061004252
            children [
              DEF lf_1_1 Shape {
                appearance Appearance {
                  material Material {
                    diffuseColor 1 1 0
                    emissiveColor 0.33333 0 0
                  }
                }
                geometry Capsule {
                  height 0.04
                  radius 0.005
                }
              }
            ]
          }
        ]
        name "lf_1_1"
        boundingObject Transform {
          translation -0.02 0 0
          rotation 0 0 1 1.5707996938995747
          children [
            USE lf_1_1
          ]
        }
        physics Physics {
          mass 0.1
        }
      }
    }
    DEF lf_2_1 HingeJoint {
      jointParameters HingeJointParameters {
        axis 0 0 1
        anchor 0.11 0 0.1
      }
      device [
        RotationalMotor {
          name "motor_lf_2"
          maxTorque 4
        }
        PositionSensor {
          name "sensor_lf_2"
        }
      ]
      endPoint DEF lf_2_1 Solid {
        translation 0.11 0 -0.1
        rotation -9.578515743039246e-08 1.931885136193727e-08 -0.9999999999999953 3.1415926640051883
        children [
          DEF lf_2_2 HingeJoint {
            jointParameters HingeJointParameters {
              axis 0 0 1
              anchor -0.04 0 0
            }
            endPoint DEF lf_2_2 Solid {
              translation -0.04 0 0
              rotation -1.8051252806291692e-06 -1.5438404772584676e-06 0.9999999999971789 0.00350334522367267
              children [
                DEF lf_2_1 HingeJoint {
                  jointParameters HingeJointParameters {
                    axis 0 0 1
                    anchor 0.06 0.0104 0
                  }
                  endPoint SolidReference {
                    solidName "lf_1_2"
                  }
                }
                Transform {
                  translation 0.03 0.052 0
                  rotation 0 0 1 2.6180003061004253
                  children [
                    DEF lf_2_2 Shape {
                      appearance Appearance {
                        material Material {
                          diffuseColor 1 1 0
                          emissiveColor 0.333333 0 0
                        }
                      }
                      geometry Capsule {
                        height 0.12
                        radius 0.005
                      }
                    }
                  ]
                }
              ]
              name "lf_2_2"
              boundingObject Transform {
                translation 0.03 0.052 0
                rotation 0 0 1 2.62
                children [
                  USE lf_2_2
                ]
              }
              physics Physics {
                mass 0.2
              }
            }
          }
          Transform {
            translation -0.02 0 0
            rotation 0 0 1 1.5707996938995747
            children [
              DEF lf_2_1 Shape {
                appearance Appearance {
                  material Material {
                    diffuseColor 1 1 0
                    emissiveColor 0.3333 0 0
                  }
                }
                geometry Capsule {
                  height 0.04
                  radius 0.005
                }
              }
            ]
          }
        ]
        name "lf_2_1"
        boundingObject Transform {
          translation -0.02 0 0
          rotation 0 0 1 1.5707996938995747
          children [
            USE lf_2_1
          ]
        }
        physics Physics {
          mass 0.1
        }
      }
    }
    DEF lr_1_1 HingeJoint {
      jointParameters HingeJointParameters {
        axis 0 0 1
        anchor -0.11 0 0.1
      }
      device [
        RotationalMotor {
          name "motor_lr_1"
          maxTorque 4
        }
        PositionSensor {
          name "sensor_lr_1"
        }
      ]
      endPoint DEF lr_1_1 Solid {
        translation -0.11 0 -0.1
        rotation 0.9687834657072881 -0.24790842414286288 9.90513895444473e-05 0.0006219473774513501
        children [
          DEF lr_1_2 HingeJoint {
            jointParameters HingeJointParameters {
              axis 0 0 1
              anchor -0.04 0 0
            }
            endPoint DEF lr_1_2 Solid {
              translation -0.04 0 0
              rotation -2.7915254077597265e-05 8.469505125924438e-05 -0.9999999960237436 4.873648417541571e-05
              children [
                DEF foot_lr TouchSensor {
                  translation 0.059 -0.104 -6.71081e-06
                  rotation -0.27012124055184816 0.15022423166634566 0.951034802529848 1.0107892372635543e-09
                  children [
                    DEF foot_lr Shape {
                      appearance Appearance {
                        material Material {
                          diffuseColor 0 0.666667 0
                        }
                      }
                      geometry Sphere {
                        radius 0.007
                        subdivision 3
                      }
                    }
                  ]
                  name "foot_lr"
                  boundingObject USE foot_lr
                  physics Physics {
                    density -1
                    mass 0.1
                  }
                  lookupTable [
                    0 0 0
                    1000 1000 0
                  ]
                }
                Transform {
                  translation 0.03 -0.052 0
                  rotation 0 0 -1 -0.5235996938995747
                  children [
                    DEF lr_1_2 Shape {
                      appearance Appearance {
                        material Material {
                          diffuseColor 1 1 0
                          emissiveColor 0.3333 0 0
                        }
                      }
                      geometry Capsule {
                        height 0.12
                        radius 0.005
                      }
                    }
                  ]
                }
              ]
              name "lr_1_2"
              boundingObject Transform {
                translation 0.03 -0.052 0
                rotation 0 0 -1 -0.5235996938995747
                children [
                  USE lr_1_2
                ]
              }
              physics Physics {
                mass 0.1
              }
            }
          }
          Transform {
            translation -0.02 0 0
            rotation 0 0 1 1.5708003061004252
            children [
              DEF lr_1_1 Shape {
                appearance Appearance {
                  material Material {
                    diffuseColor 1 1 0
                    emissiveColor 0.33333 0 0
                  }
                }
                geometry Capsule {
                  height 0.04
                  radius 0.005
                }
              }
            ]
          }
        ]
        name "lr_1_1"
        boundingObject Transform {
          translation -0.02 0 0
          rotation 0 0 1 1.5707996938995747
          children [
            USE lr_1_1
          ]
        }
        physics Physics {
          mass 0.1
        }
      }
    }
    DEF lr_2_1 HingeJoint {
      jointParameters HingeJointParameters {
        axis 0 0 1
        anchor -0.07 0 0.12
      }
      device [
        RotationalMotor {
          name "motor_lr_2"
          maxTorque 4
        }
        PositionSensor {
          name "sensor_lr_2"
        }
      ]
      endPoint DEF lr_2_1 Solid {
        translation -0.07 0 -0.1
        rotation -4.6697018718828303e-07 -9.726874166363234e-07 0.999999999999418 3.1415927025937367
        children [
          DEF lr_2_2 HingeJoint {
            jointParameters HingeJointParameters {
              axis 0 0 1
              anchor -0.04 0 0
            }
            endPoint DEF lr_2_2 Solid {
              translation -0.04 0 0
              rotation 3.0287108021381256e-06 -4.706717166212341e-06 0.9999999999843368 0.0035033452188557314
              children [
                DEF lr_2_1 HingeJoint {
                  jointParameters HingeJointParameters {
                    axis 0 0 1
                    anchor 0.059 0.104 0
                  }
                  endPoint SolidReference {
                    solidName "lr_1_2"
                  }
                }
                Transform {
                  translation 0.031 0.052 0
                  rotation 0 0 1 2.59
                  children [
                    DEF lr_2_2 Shape {
                      appearance Appearance {
                        material Material {
                          diffuseColor 1 1 0
                          emissiveColor 0.333333 0 0
                        }
                      }
                      geometry Capsule {
                        height 0.12
                        radius 0.005
                      }
                    }
                  ]
                }
              ]
              name "lr_2_2"
              boundingObject Transform {
                translation 0.031 0.052 0
                rotation 0 0 1 2.59
                children [
                  USE lr_2_2
                ]
              }
              physics Physics {
                mass 0.2
              }
            }
          }
          Transform {
            translation -0.02 0 0
            rotation 0 0 1 -1.5707996938995747
            children [
              DEF lr_2_1 Shape {
                appearance Appearance {
                  material Material {
                    diffuseColor 1 1 0
                    emissiveColor 0.3333 0 0
                  }
                }
                geometry Capsule {
                  height 0.04
                  radius 0.005
                }
              }
            ]
          }
        ]
        name "rf_2_1(3)"
        boundingObject Transform {
          translation -0.02 0 0
          rotation 0 0 1 1.5707996938995747
          children [
            USE lr_2_1
          ]
        }
        physics Physics {
          mass 0.1
        }
      }
    }
  ]
  boundingObject USE body
  physics Physics {
    density 1
    mass 2
  }
  controller "test"
}
CircleArena {
  radius 10
  floorAppearance Appearance {
    material Material {
      diffuseColor 0.4 0.2 0.1
    }
  }
}
